# await 与故障恢复

在没有执行到 await 时，如果被打断或者因为其他的原因程序执行崩溃，但在堆中保存的数据没有被损坏，则下一次继续执行该任务时，可以从上一次 await 的点继续执行。